Workbook

Sheet cox_model
A1: id | B1: time | C1: status | D1: stage_at_death | E1: Plant_species | F1: Treatment | G1: Survival_to_pupa
A2: PF1.1a | B2: =Larvae!AF34-Larvae!C34 -> 22 | C2: 0 | E2: M. aquaticum | F2: Control | G2: 1 | O2: status = 0 | P2: survival until pupa!!!
A3: PF1.2a | B3: =Larvae!V35-Larvae!C35 -> 17 | C3: 0 | E3: M. aquaticum | F3: Control | G3: 1 | O3: status = 1 | P3: the event happened,= dead
A4: PF2.1a | B4: 1 | C4: 1 | E4: M. aquaticum | F4: Control | G4: 0
A5: PF2.2a | B5: =Larvae!V37-Larvae!C37 -> 17 | C5: 0 | E5: M. aquaticum | F5: Control | G5: 1
A6: PF3.1a | B6: =Larvae!L38-Larvae!C38+1 -> 13 | C6: 1 | E6: M. aquaticum | F6: Control | G6: 0
A7: PF3.2a | B7: 1 | C7: 1 | E7: M. aquaticum | F7: Control | G7: 0
A8: PF4.1a | B8: 1 | C8: 1 | E8: M. aquaticum | F8: Control | G8: 0
A9: PF4.2a | B9: =Larvae!V41-Larvae!C41 -> 17 | C9: 0 | E9: M. aquaticum | F9: Control | G9: 1
A10: PF5.1a | B10: 1 | C10: 1 | E10: M. aquaticum | F10: Control | G10: 0
A11: PF5.2a | B11: =Larvae!V43-Larvae!C43 -> 17 | C11: 0 | E11: M. aquaticum | F11: Control | G11: 1
A12: PF6.1a | B12: =Larvae!P44-Larvae!C44 -> 14 | C12: 0 | E12: M. aquaticum | F12: Control | G12: 1
A13: PF6.2a | B13: 1 | C13: 1 | E13: M. aquaticum | F13: Control | G13: 0
A14: PF7.1a | B14: =Larvae!V46-Larvae!C46 -> 17 | C14: 0 | E14: M. aquaticum | F14: Herbivory 5 days | G14: 1
A15: PF7.2a | B15: 1 | C15: 1 | E15: M. aquaticum | F15: Herbivory 5 days | G15: 0
A16: PF8.1a | B16: =Larvae!AD48-Larvae!C48 -> 21 | C16: 0 | E16: M. aquaticum | F16: Herbivory 5 days | G16: 1
A17: PF8.2a | B17: =Larvae!V49-Larvae!C49 -> 17 | C17: 0 | E17: M. aquaticum | F17: Herbivory 5 days | G17: 1
A18: PF9.1a | B18: =Larvae!F50-Larvae!C50+1 -> 6 | C18: 1 | E18: M. aquaticum | F18: Herbivory 5 days | G18: 0
A19: PF9.2a | B19: =1 -> 1 | C19: 1 | E19: M. aquaticum | F19: Herbivory 5 days | G19: 0
A20: PF10.1a | B20: =Larvae!Z52-Larvae!C52 -> 19 | C20: 0 | E20: M. aquaticum | F20: Herbivory 5 days | G20: 1
A21: PF10.2a | B21: =Larvae!F53-Larvae!C53+1 -> 6 | C21: 1 | E21: M. aquaticum | F21: Herbivory 5 days | G21: 0
A22: PF11.1a | B22: =Larvae!F54-Larvae!C54+1 -> 6 | C22: 1 | E22: M. aquaticum | F22: Herbivory 5 days | G22: 0
A23: PF11.2a | B23: 1 | C23: 1 | E23: M. aquaticum | F23: Herbivory 5 days | G23: 0
A24: PF12.1a | B24: =Larvae!Z56-Larvae!C56 -> 19 | C24: 0 | E24: M. aquaticum | F24: Herbivory 5 days | G24: 1
A25: PF12.2a | B25: 1 | C25: 1 | E25: M. aquaticum | F25: Herbivory 5 days | G25: 0
A30: id | B30: time | C30: status | D30: stage_at_death | E30: Plant_species | F30: Treatment | G30: Survival_to_pupa
A31: PP1.1 | B31: =Larvae!L58-Larvae!C58+1 -> 13 | C31: 1 | E31: P. palustris | F31: Control | G31: 0
A32: PP1.2 | B32: =Larvae!H59-Larvae!C59+1 -> 8 | C32: 1 | E32: P. palustris | F32: Control | G32: 0
A33: PP2.1 | B33: 1 | C33: 1 | E33: P. palustris | F33: Control | G33: 0
A34: PP2.2 | B34: =Larvae!AF61-Larvae!C61 -> 22 | C34: 1 | E34: P. palustris | F34: Control | G34: 0
A35: PP3.1 | B35: 1 | C35: 1 | E35: P. palustris | F35: Control | G35: 0
A36: PP3.2 | B36: 1 | C36: 1 | E36: P. palustris | F36: Control | G36: 0
A37: PP4.1 | B37: 1 | C37: 1 | E37: P. palustris | F37: Control | G37: 0
A38: PP4.2 | B38: 1 | C38: 1 | E38: P. palustris | F38: Control | G38: 0
A39: PP5.1 | B39: 1 | C39: 1 | E39: P. palustris | F39: Control | G39: 0
A40: PP5.2 | B40: =1 -> 1 | C40: 1 | E40: P. palustris | F40: Control | G40: 0
A41: PP6.1 | B41: =Larvae!J68-Larvae!C68+1 -> 10 | C41: 1 | E41: P. palustris | F41: Control | G41: 0
A42: PP6.2 | B42: 1 | C42: 1 | E42: P. palustris | F42: Control | G42: 0
A43: PP7.1 | B43: =Larvae!H70-Larvae!C70+1 -> 8 | C43: 1 | E43: P. palustris | F43: Herbivory 5 days | G43: 0
A44: PP7.2 | B44: 1 | C44: 1 | E44: P. palustris | F44: Herbivory 5 days | G44: 0
...

Sheet Larvae
A1: Rep | B1: Plant_sp | C1: Date_larvae | D1: Check_date_1 | E1: Head_capsule_width_1_mm | F1: Check_date_2 | G1: Head_capsule_width_2_mm | H1: Check_date_3 | I1: Head_capsule_width_3_mm | J1: Check_date_4 | K1: Head_capsule_width_4_mm | L1: Check_date_5 | M1: Head_capsule_width_5_mm | N1: Check_date_6 | O1: Head_capsule_width_6_mm | P1: Check_date_7 | Q1: Head_capsule_width_7_mm | R1: Check_date_8 | S1: Head_capsule_width_8_mm | T1: Check_date_9 | U1: Head_capsule_width_9_mm | V1: Check_date_10 | W1: Head_capsule_width_10_mm | X1: Check_date_11 | Y1: Head_capsule_width_11_mm | Z1: Remarks (emerged). Numbers are for the feeding score after the 5days exposure
A2: PF10.1 | B2: M. aquaticum | C2: 45901 | D2: 45903 | E2: 0.24 | F2: 45905 | G2: 0.3 | H2: 45908 | I2: 0.36 | J2: 45909 | K2: 0.42 | L2: 45910 | M2: 0.42 | N2: 45911 | O2: 0.42 | P2: 45912 | Q2: 0.48 | Z2: 11/09: larva not very active. 12/09/2025: larva dead
A3: PF10.2 | B3: M. aquaticum | C3: 45901 | D3: 45903 | E3: 0.24 | F3: 45905 | G3: 0.3 | H3: 45908 | I3: 0.36 | J3: 45909 | K3: 0.42 | L3: 45910 | M3: 0.42 | N3: 45911 | O3: 0.6 | P3: 45912 | Q3: 0.66 | R3: 45915 | S3: 0.66 | T3: 45917 | U3: prepupal stage | V3: 45919 | W3: pupa | X3: 45925 | Y3: adult | Z3: the larva pupated on PF
A4: PF11.1 | B4: M. aquaticum | C4: 45901 | D4: 45903 | E4: 0.24 | F4: 45905 | G4: 0.42 | H4: 45908 | I4: 0.42 | J4: 45909 | K4: 0.54 | L4: 45910 | M4: 0.66 | N4: 45911 | O4: 0.66 | P4: 45912 | Q4: 0.66 | R4: 45915 | S4: 0.66 | T4: 45917 | U4: prepupal stage | V4: 45919 | W4: pupa | X4: 45925 | Y4: adult | Z4: the larva pupated on PF
A5: PF11.2 | B5: M. aquaticum | C5: 45901 | D5: 45903 | E5: 0.24 | F5: 45905 | G5: 0.3 | H5: 45908 | I5: 0.36 | J5: 45909 | K5: 0.42 | L5: 45910 | M5: 0.66 | N5: 45911 | O5: 0.66 | P5: 45912 | Q5: 0.66 | R5: 45915 | S5: 0.66 | T5: 45917 | U5: prepupal stage | V5: 45919 | W5: pupa | X5: 45925 | Y5: adult | Z5: the larva pupated on PF
A6: PF12.1 | B6: M. aquaticum | C6: 45901 | D6: 45903 | E6: 0.24 | L6: 45910 | Z6: 10/09/2025: larva dead
A7: PF12.2 | B7: M. aquaticum | C7: 45901 | D7: 45903 | E7: 0.24 | F7: 45905 | G7: 0.3
A8: MV7.1 | B8: M. verticillatum | C8: 45901 | D8: 45903 | E8: 0.18
A9: MV7.2 | B9: M. verticillatum | C9: 45901 | D9: 45903 | E9: 0.24
A10: MV8.1 | B10: M. verticillatum | C10: 45901 | D10: 45903 | F10: 45905 | G10: 0.24
A11: MV8.2 | B11: M. verticillatum | C11: 45901 | D11: 45903
A12: MV9.1 | B12: M. verticillatum | C12: 45901 | D12: 45903 | E12: 0.24 | F12: 45905 | G12: 0.24 | H12: 45908 | I12: 0.36 | J12: 45909 | K12: 0.6 | L12: 45910 | M12: 0.6 | N12: 45911 | O12: 0.6 | P12: 45912 | Q12: 0.6 | R12: 45915 | S12: 0.6
A13: MV9.2 | B13: M. verticillatum | C13: 45901 | D13: 45903 | E13: 0.21
A14: MV10.1 | B14: M. verticillatum | C14: 45901 | D14: 45903
A15: MV10.2 | B15: M. verticillatum | C15: 45901 | D15: 45903
A16: MV11.1 | B16: M. verticillatum | C16: 45901 | D16: 45903 | F16: 45905 | G16: 0.3 | H16: 45908 | I16: 0.36 | J16: 45909 | K16: 0.6 | L16: 45910 | M16: 0.6 | N16: 45911 | O16: 0.6 | P16: 45912 | Q16: 0.6 | R16: 45915 | S16: 0.66 | T16: 45917 | U16: prepupal stage | V16: 45919 | W16: pupa | X16: 45925 | Y16: adult | Z16: the larva pupated on the wall of the cylinder
A17: MV11.2 | B17: M. verticillatum | C17: 45901 | D17: 45903
A18: MV12.1 | B18: M. verticillatum | C18: 45901 | D18: 45903 | E18: 0.24 | N18: 45911 | O18: 0.42 | Z18: 11/09/2025: larva dead
A19: MV12.2 | B19: M. verticillatum | C19: 45901 | D19: 45903
A20: MH7.1 | B20: M. heterophyllum | C20: 45901 | D20: 45903 | Z20: 03/09/2025: larva dead
A21: MH7.2 | B21: M. heterophyllum | C21: 45901 | D21: 45903 | E21: 0.18 | F21: 45905 | G21: 0.24 | H21: 45908 | I21: 0.3
A22: MH8.1 | B22: M. heterophyllum | C22: 45901 | D22: 45903
A23: MH8.2 | B23: M. heterophyllum | C23: 45901 | D23: 45903 | E23: 0.18 | Z23: the larva wasn't very active (on the 03/09/2025)
A24: MH9.1 | B24: M. heterophyllum | C24: 45901 | D24: 45903 | E24: 0.18 | Z24: the larva was found in the water (on the 03/09/2025)
A25: MH9.2 | B25: M. heterophyllum | C25: 45901 | D25: 45903 | E25: 0.24 | F25: 45905 | G25: 0.48 | H25: 45908 | I25: 0.6 | J25: 45909 | K25: 0.6 | L25: 45910 | M25: 0.6 | N25: 45911 | O25: 0.6 | Z25: 11/09/2025: larva dead
A26: MH10.1 | B26: M. heterophyllum | C26: 45901 | D26: 45903 | E26: 0.24
A27: MH10.2 | B27: M. heterophyllum | C27: 45901 | D27: 45903 | F27: 45905 | G27: 0.24 | H27: 45908 | Z27: 08/09/2025: larva dead
A28: MH11.1 | B28: M. heterophyllum | C28: 45901 | D28: 45903
A29: MH11.2 | B29: M. heterophyllum | C29: 45901 | D29: 45903 | Z29: I think the larva was dead (03/09/2025)
A30: MH12.1 | B30: M. heterophyllum | C30: 45901 | D30: 45903 | E30: 0.24 | Z30: larva found in the water and wasn't very active (03/09/2025)
A31: MH12.2 | B31: M. heterophyllum | C31: 45901 | D31: 45903 | E31: 0.24 | F31: 45905 | Z31: 05/09/2025: larva dead
A33: Rep | B33: Plant_species | C33: Date_larvae | D33: Check_date_1 | E33: HCW_1 | F33: Check_date_2 | G33: HCW_2 | H33: Check_date_3 | I33: HCW_3 | J33: Check_date_4 | K33: HCW_4 | L33: Check_date_5 | M33: HCW_5 | N33: Check_date_6 | O33: HCW_6 | P33: Check_date_7 | Q33: HCW_7 | R33: Check_date_8 | S33: HCW_8 | T33: Check_date_9 | U33: HCW_9 | V33: Check_date_10 | W33: HCW_10 | X33: Check_date_11 | Y33: HCW_11 | Z33: Check_date_12 | AA33: HCW_12 | AB33: Check_date_13 | AC33: HCW_13 | AD33: Check_date_14 | AE33: HCW_14 | AF33: Check_date_15 | AG33: HCW_15 | AH33: Check_date_16 | AI33: HCW_16 | AJ33: Check_date_17 | AK33: HCW_17 | AL33: Check_date_18 | AM33: HCW_18 | AN33: Check_date_19 | AO33: HCW_19 | AP33: Check_date_20 | AQ33: HCW_20
A34: PF1.1a | B34: M. aquaticum | C34: 45938 | F34: 45943 | G34: 0.3 | H34: 45945 | I34: 0.3 | J34: 45947 | K34: 0.42 | L34: 45950 | M34: 0.66 | N34: 45951 | P34: 45952 | Q34: 0.66 | R34: 45953 | S34: 0.72 | T34: 45954 | U34: prepupal stage | V34: 45955 | W34: prepupal stage | X34: 45956 | Y34: prepupal stage | Z34: 45957 | AA34: prepupal stage | AB34: 45958 | AC34: prepupal stage | AD34: 45959 | AE34: prepupal stage | AF34: 45960 | AG34: pupa | AH34: 45961 | AJ34: 45962 | AL34: 45963 | AN34: 45964 | AO34: adult
A35: PF1.2a | B35: M. aquaticum | C35: 45938 | F35: 45943 | G35: 0.3 | H35: 45945 | I35: 0.48 | J35: 45947 | K35: 0.66 | L35: 45950 | M35: 0.66 | N35: 45951 | P35: 45952 | Q35: prepupal stage | R35: 45953 | S35: prepupal stage | T35: 45954 | U35: prepupal stage | V35: 45955 | W35: pupa | X35: 45956 | Z35: 45957 | AB35: 45958 | AD35: 45959 | AF35: 45960 | AG35: adult | AH35: 45961 | AJ35: 45962 | AL35: 45963 | AN35: 45964
A36: PF2.1a | B36: M. aquaticum | C36: 45938 | F36: 45943 | H36: 45945 | J36: 45947 | L36: 45950 | N36: 45951 | P36: 45952 | R36: 45953 | T36: 45954 | V36: 45955 | X36: 45956 | Z36: 45957 | AB36: 45958 | AD36: 45959 | AF36: 45960 | AH36: 45961 | AJ36: 45962 | AL36: 45963 | AN36: 45964
A37: PF2.2a | B37: M. aquaticum | C37: 45938 | F37: 45943 | G37: 0.48 | H37: 45945 | I37: 0.48 | J37: 45947 | K37: 0.66 | L37: 45950 | M37: 0.72 | N37: 45951 | O37: prepupal stage | P37: 45952 | Q37: prepupal stage | R37: 45953 | S37: prepupal stage | T37: 45954 | U37: prepupal stage | V37: 45955 | W37: pupa | X37: 45956 | Z37: 45957 | AB37: 45958 | AD37: 45959 | AF37: 45960 | AG37: adult | AH37: 45961 | AJ37: 45962 | AL37: 45963 | AN37: 45964
A38: PF3.1a | B38: M. aquaticum | C38: 45938 | F38: 45943 | G38: 0.3 | H38: 45945 | J38: 45947 | K38: 0.3 | L38: 45950 | M38: 0.3 | N38: 45951 | P38: 45952 | Q38: 0,3 larva dead | R38: 45953 | T38: 45954 | V38: 45955 | X38: 45956 | Z38: 45957 | AB38: 45958 | AD38: 45959 | AF38: 45960 | AH38: 45961 | AJ38: 45962 | AL38: 45963 | AN38: 45964
A39: PF3.2a | B39: M. aquaticum | C39: 45938 | F39: 45943 | G39: larva dead | H39: 45945 | J39: 45947 | L39: 45950 | N39: 45951 | P39: 45952 | R39: 45953 | T39: 45954 | V39: 45955 | X39: 45956 | Z39: 45957 | AB39: 45958 | AD39: 45959 | AF39: 45960 | AH39: 45961 | AJ39: 45962 | AL39: 45963 | AN39: 45964
A40: PF4.1a | B40: M. aquaticum | C40: 45938 | F40: 45943 | G40: larva dead | H40: 45945 | J40: 45947 | L40: 45950 | N40: 45951 | P40: 45952 | R40: 45953 | T40: 45954 | V40: 45955 | X40: 45956 | Z40: 45957 | AB40: 45958 | AD40: 45959 | AF40: 45960 | AH40: 45961 | AJ40: 45962 | AL40: 45963 | AN40: 45964
A41: PF4.2a | B41: M. aquaticum | C41: 45938 | F41: 45943 | G41: 0.42 | H41: 45945 | I41: 0.42 | J41: 45947 | K41: 0.6 | L41: 45950 | M41: 0.66 | N41: 45951 | P41: 45952 | Q41: prepupal stage | R41: 45953 | S41: prepupal stage | T41: 45954 | U41: prepupal stage | V41: 45955 | W41: pupa | X41: 45956 | Z41: 45957 | AB41: 45958 | AD41: 45959 | AF41: 45960 | AG41: adult | AH41: 45961 | AJ41: 45962 | AL41: 45963 | AN41: 45964
...
